# request:


test raised exception 'HOST_NAME':
Traceback (most recent call last):
  File "/home/arau/lumoa/src/booktest/booktest/testrun.py", line 105, in run_case
    rv = await maybe_async_call(case, [t], {})
         ^^^^^^^^^^^^^^^^^^^^^^^^^^^^^^^^^^^^^
  File "/home/arau/lumoa/src/booktest/booktest/coroutines.py", line 6, in maybe_async_call
    return await func(*args2, **kwargs)
           ^^^^^^^^^^^^^^^^^^^^^^^^^^^^
  File "/home/arau/lumoa/src/booktest/booktest/env.py", line 128, in wrapper
    return await maybe_async_call(func, args, kwargs)
           ^^^^^^^^^^^^^^^^^^^^^^^^^^^^^^^^^^^^^^^^^^
  File "/home/arau/lumoa/src/booktest/booktest/coroutines.py", line 6, in maybe_async_call
    return await func(*args2, **kwargs)
           ^^^^^^^^^^^^^^^^^^^^^^^^^^^^
  File "/home/arau/lumoa/src/booktest/booktest/env.py", line 190, in wrapper
    return await maybe_async_call(func, args, kwargs)
           ^^^^^^^^^^^^^^^^^^^^^^^^^^^^^^^^^^^^^^^^^^
  File "/home/arau/lumoa/src/booktest/booktest/coroutines.py", line 6, in maybe_async_call
    return await func(*args2, **kwargs)
           ^^^^^^^^^^^^^^^^^^^^^^^^^^^^
  File "/home/arau/lumoa/src/booktest/booktest/requests.py", line 489, in wrapper
    return await maybe_async_call(func , args, kwargs)
           ^^^^^^^^^^^^^^^^^^^^^^^^^^^^^^^^^^^^^^^^^^^
  File "/home/arau/lumoa/src/booktest/booktest/coroutines.py", line 8, in maybe_async_call
    return func(*args2, **kwargs)
           ^^^^^^^^^^^^^^^^^^^^^^
  File "/home/arau/lumoa/src/booktest/test/examples/snapshots_book.py", line 196, in test_requests_and_env
    host_name = os.environ["HOST_NAME"]
                ~~~~~~~~~~^^^^^^^^^^^^^
  File "<frozen os>", line 679, in __getitem__
KeyError: 'HOST_NAME'

